<sdf version='1.9'>
  <model name='sim_Assem.SLDASM'>
    <link name='base_link'>
      <inertial>
        <pose>0.34206 -0.05604 0.22506 0 0 0</pose>
        <mass>14.792999999999999</mass>
        <inertia>
          <ixx>0.11862</ixx>
          <ixy>-7.5813000000000001e-05</ixy>
          <ixz>-7.9720000000000002e-05</ixz>
          <iyy>0.77188000000000001</iyy>
          <iyz>-8.0370000000000005e-05</iyz>
          <izz>0.75785999999999998</izz>
        </inertia>
      </inertial>
      <collision name='base_link_collision'>
        <pose>0 0 0 0 0 0</pose>
        <geometry>
          <mesh>
            <scale>1 1 1</scale>
            <uri>file:///home/thinh/ros2_ws/src/gzb_sim_pkg/meshes/base_link.STL</uri>
          </mesh>
        </geometry>
      </collision>
      <visual name='base_link_visual'>
        <pose>0 0 0 0 0 0</pose>
        <geometry>
          <mesh>
            <scale>1 1 1</scale>
            <uri>file:///home/thinh/ros2_ws/src/gzb_sim_pkg/meshes/base_link.STL</uri>
          </mesh>
        </geometry>
        <material>
          <diffuse>0.9902 1 1 1</diffuse>
          <ambient>0.9902 1 1 1</ambient>
        </material>
      </visual>
    </link>
    <joint name='joint1' type='prismatic'>
      <pose relative_to='base_link'>0 0 0 0 0 0</pose>
      <parent>base_link</parent>
      <child>link1</child>
      <axis>
        <xyz>1 0 0</xyz>
        <limit>
          <lower>0</lower>
          <upper>500</upper>
          <effort>0</effort>
          <velocity>0</velocity>
        </limit>
        <dynamics>
          <spring_reference>0</spring_reference>
          <spring_stiffness>0</spring_stiffness>
        </dynamics>
      </axis>
    </joint>
    <link name='link1'>
      <pose relative_to='joint1'>0 0 0 0 0 0</pose>
      <inertial>
        <pose>0.05303 0.076941 -0.048359 0 0 0</pose>
        <mass>1.2717000000000001</mass>
        <inertia>
          <ixx>0.0087530000000000004</ixx>
          <ixy>0.00015469999999999999</ixy>
          <ixz>1.5204000000000001e-06</ixz>
          <iyy>0.00091752999999999995</iyy>
          <iyz>-7.5753000000000005e-05</iyz>
          <izz>0.0094082999999999996</izz>
        </inertia>
      </inertial>
      <collision name='link1_collision'>
        <pose>0 0 0 0 0 0</pose>
        <geometry>
          <mesh>
            <scale>1 1 1</scale>
            <uri>file:///home/thinh/ros2_ws/src/gzb_sim_pkg/meshes/link1.STL</uri>
          </mesh>
        </geometry>
      </collision>
      <visual name='link1_visual'>
        <pose>0 0 0 0 0 0</pose>
        <geometry>
          <mesh>
            <scale>1 1 1</scale>
            <uri>file:///home/thinh/ros2_ws/src/gzb_sim_pkg/meshes/link1.STL</uri>
          </mesh>
        </geometry>
        <material>
          <diffuse>0.9902 1 1 1</diffuse>
          <ambient>0.9902 1 1 1</ambient>
        </material>
      </visual>
    </link>
    <joint name='joint2' type='prismatic'>
      <pose relative_to='link1'>0 0 0 0 0 0</pose>
      <parent>link1</parent>
      <child>link2</child>
      <axis>
        <xyz>0 -1 0</xyz>
        <limit>
          <lower>0</lower>
          <upper>195</upper>
          <effort>0</effort>
          <velocity>0.5</velocity>
        </limit>
        <dynamics>
          <spring_reference>0</spring_reference>
          <spring_stiffness>0</spring_stiffness>
        </dynamics>
      </axis>
    </joint>
    <link name='link2'>
      <pose relative_to='joint2'>0 0 0 0 0 0</pose>
      <inertial>
        <pose>0.10476 0.12206 -0.15295 0 0 0</pose>
        <mass>0.55701000000000001</mass>
        <inertia>
          <ixx>0.0010679999999999999</ixx>
          <ixy>-1.5274e-06</ixy>
          <ixz>2.2008999999999999e-05</ixz>
          <iyy>0.0010652999999999999</iyy>
          <iyz>-3.0877999999999999e-06</iyz>
          <izz>0.00025901</izz>
        </inertia>
      </inertial>
      <collision name='link2_collision'>
        <pose>0 0 0 0 0 0</pose>
        <geometry>
          <mesh>
            <scale>1 1 1</scale>
            <uri>file:///home/thinh/ros2_ws/src/gzb_sim_pkg/meshes/link2.STL</uri>
          </mesh>
        </geometry>
      </collision>
      <visual name='link2_visual'>
        <pose>0 0 0 0 0 0</pose>
        <geometry>
          <mesh>
            <scale>1 1 1</scale>
            <uri>file:///home/thinh/ros2_ws/src/gzb_sim_pkg/meshes/link2.STL</uri>
          </mesh>
        </geometry>
        <material>
          <diffuse>0.9902 1 1 1</diffuse>
          <ambient>0.9902 1 1 1</ambient>
        </material>
      </visual>
    </link>
    <joint name='joint3' type='prismatic'>
      <pose relative_to='link2'>0 0 0 0 0 0</pose>
      <parent>link2</parent>
      <child>link3</child>
      <axis>
        <xyz>0 0 -1</xyz>
        <limit>
          <lower>0</lower>
          <upper>60</upper>
          <effort>0</effort>
          <velocity>0.5</velocity>
        </limit>
        <dynamics>
          <spring_reference>0</spring_reference>
          <spring_stiffness>0</spring_stiffness>
        </dynamics>
      </axis>
    </joint>
    <link name='link3'>
      <pose relative_to='joint3'>0 0 0 0 0 0</pose>
      <inertial>
        <pose>0.15464 0.12214 -0.10245 0 0 0</pose>
        <mass>0.17487</mass>
        <inertia>
          <ixx>0.00019395</ixx>
          <ixy>9.1119000000000003e-09</ixy>
          <ixz>2.1314000000000001e-08</ixz>
          <iyy>0.00015856999999999999</iyy>
          <iyz>-7.1182000000000003e-10</iyz>
          <izz>5.0460999999999997e-05</izz>
        </inertia>
      </inertial>
      <collision name='link3_collision'>
        <pose>0 0 0 0 0 0</pose>
        <geometry>
          <mesh>
            <scale>1 1 1</scale>
            <uri>file:///home/thinh/ros2_ws/src/gzb_sim_pkg/meshes/link3.STL</uri>
          </mesh>
        </geometry>
      </collision>
      <visual name='link3_visual'>
        <pose>0 0 0 0 0 0</pose>
        <geometry>
          <mesh>
            <scale>1 1 1</scale>
            <uri>file:///home/thinh/ros2_ws/src/gzb_sim_pkg/meshes/link3.STL</uri>
          </mesh>
        </geometry>
        <material>
          <diffuse>0.9902 1 1 1</diffuse>
          <ambient>0.9902 1 1 1</ambient>
        </material>
      </visual>
    </link>
    <plugin filename="libign_ros2_control-system.so" name="ign_ros2_control">
      <parameters>/home/thinh/ros2_ws/src/gzb_sim_pkg/config/ros2_control.yaml</parameters>
    </plugin>
  </model>
</sdf>
